Traceback (most recent call last):
  File "/app/iambic/plugins/v0_1_0/github/github.py", line 558, in wrapped_workflow_func
    template_changes = workflow_func(repo_url, default_branch)
                       ^^^^^^^^^^^^^^^^^^^^^^^^^^^^^^^^^^^^^^^
  File "/app/iambic/plugins/v0_1_0/github/github.py", line 723, in _handle_import
    raise e
  File "/app/iambic/plugins/v0_1_0/github/github.py", line 712, in _handle_import
    config = asyncio.run(load_config(config_path))
             ^^^^^^^^^^^^^^^^^^^^^^^^^^^^^^^^^^^^^
  File "/Python-3.11.1/Lib/asyncio/runners.py", line 190, in run
    return runner.run(main)
           ^^^^^^^^^^^^^^^^
  File "/Python-3.11.1/Lib/asyncio/runners.py", line 118, in run
    return self._loop.run_until_complete(task)
           ^^^^^^^^^^^^^^^^^^^^^^^^^^^^^^^^^^^
  File "/Python-3.11.1/Lib/asyncio/base_events.py", line 653, in run_until_complete
    return future.result()
           ^^^^^^^^^^^^^^^
  File "/app/iambic/config/dynamic_config.py", line 457, in load_config
    return await process_config(
           ^^^^^^^^^^^^^^^^^^^^^
  File "/app/iambic/config/dynamic_config.py", line 495, in process_config
    await config.configure_plugins()
  File "/app/iambic/config/dynamic_config.py", line 343, in configure_plugins
    await plugin.async_load_callable(self.get_config_plugin(plugin))
  File "/app/iambic/plugins/v0_1_0/aws/handlers.py", line 69, in load
    orgs_accounts = await asyncio.gather(
                    ^^^^^^^^^^^^^^^^^^^^^
  File "/app/iambic/plugins/v0_1_0/aws/models.py", line 642, in get_accounts
    org_accounts = await legacy_paginated_search(
                   ^^^^^^^^^^^^^^^^^^^^^^^^^^^^^^
  File "/app/iambic/plugins/v0_1_0/aws/utils.py", line 172, in legacy_paginated_search
    response = await boto_crud_call(search_fnc, **search_kwargs)
               ^^^^^^^^^^^^^^^^^^^^^^^^^^^^^^^^^^^^^^^^^^^^^^^^^
  File "/app/iambic/plugins/v0_1_0/aws/utils.py", line 46, in boto_crud_call
    return await aio_wrapper(boto_fnc, **kwargs)
           ^^^^^^^^^^^^^^^^^^^^^^^^^^^^^^^^^^^^^
  File "/app/iambic/core/utils.py", line 162, in aio_wrapper
    return await sync_to_async(fnc, thread_sensitive=thread_sensitive)(*args, **kwargs)
           ^^^^^^^^^^^^^^^^^^^^^^^^^^^^^^^^^^^^^^^^^^^^^^^^^^^^^^^^^^^^^^^^^^^^^^^^^^^^
  File "/usr/local/lib/python3.11/site-packages/asgiref/sync.py", line 448, in __call__
    ret = await asyncio.wait_for(future, timeout=None)
          ^^^^^^^^^^^^^^^^^^^^^^^^^^^^^^^^^^^^^^^^^^^^
  File "/Python-3.11.1/Lib/asyncio/tasks.py", line 442, in wait_for
    return await fut
           ^^^^^^^^^
  File "/Python-3.11.1/Lib/concurrent/futures/thread.py", line 58, in run
    result = self.fn(*self.args, **self.kwargs)
             ^^^^^^^^^^^^^^^^^^^^^^^^^^^^^^^^^^
  File "/usr/local/lib/python3.11/site-packages/asgiref/sync.py", line 490, in thread_handler
    return func(*args, **kwargs)
           ^^^^^^^^^^^^^^^^^^^^^
  File "/usr/local/lib/python3.11/site-packages/botocore/client.py", line 530, in _api_call
    return self._make_api_call(operation_name, kwargs)
           ^^^^^^^^^^^^^^^^^^^^^^^^^^^^^^^^^^^^^^^^^^^
  File "/usr/local/lib/python3.11/site-packages/botocore/client.py", line 960, in _make_api_call
    raise error_class(parsed_response, operation_name)
botocore.errorfactory.ServiceException: An error occurred (ServiceException) when calling the ListAccounts operation (reached max retries: 4): AWS Organizations can't complete your request because there was an internal service error. Try again later.
